<?xml version="1.0" ?>
<robot name="ArmAssembly">

<material name="silver">
  <color rgba="0.700 0.700 0.700 1.000"/>
</material>

<link name="base_link">
  <inertial>
    <origin xyz="0.0 0.0 0.0" rpy="0 0 0"/>
    <mass value="0.0"/>
    <inertia ixx="0.0" iyy="0.0" izz="0.0" ixy="0.0" iyz="0.0" ixz="0.0"/>
  </inertial>
  <visual>
    <origin xyz="0 0 0" rpy="0 0 0"/>
    <geometry>
      <mesh filename="meshes/base_link.stl" scale="0.001 0.001 0.001"/>
    </geometry>
    <material name="silver"/>
    <material/>
  </visual>
  <collision>
    <origin xyz="0 0 0" rpy="0 0 0"/>
    <geometry>
      <mesh filename="meshes/base_link.stl" scale="0.001 0.001 0.001"/>
    </geometry>
  </collision>
</link>

<link name="ARM.1base_servo1">
  <inertial>
    <origin xyz="-9e-06 -9e-06 -0.009" rpy="0 0 0"/>
    <mass value="0.0"/>
    <inertia ixx="0.0" iyy="0.0" izz="0.0" ixy="0.0" iyz="0.0" ixz="0.0"/>
  </inertial>
  <visual>
    <origin xyz="-9e-06 -9e-06 -0.009" rpy="0 0 0"/>
    <geometry>
      <mesh filename="meshes/ARM.1base_servo1.stl" scale="0.001 0.001 0.001"/>
    </geometry>
    <material name="silver"/>
    <material/>
  </visual>
  <collision>
    <origin xyz="-9e-06 -9e-06 -0.009" rpy="0 0 0"/>
    <geometry>
      <mesh filename="meshes/ARM.1base_servo1.stl" scale="0.001 0.001 0.001"/>
    </geometry>
  </collision>
</link>

<link name="ARM.1joint_one_body1">
  <inertial>
    <origin xyz="0.034141 -9e-06 -0.0276" rpy="0 0 0"/>
    <mass value="0.0"/>
    <inertia ixx="0.0" iyy="0.0" izz="0.0" ixy="0.0" iyz="0.0" ixz="0.0"/>
  </inertial>
  <visual>
    <origin xyz="0.034141 -9e-06 -0.0276" rpy="0 0 0"/>
    <geometry>
      <mesh filename="meshes/ARM.1joint_one_body1.stl" scale="0.001 0.001 0.001"/>
    </geometry>
    <material name="silver"/>
    <material/>
  </visual>
  <collision>
    <origin xyz="0.034141 -9e-06 -0.0276" rpy="0 0 0"/>
    <geometry>
      <mesh filename="meshes/ARM.1joint_one_body1.stl" scale="0.001 0.001 0.001"/>
    </geometry>
  </collision>
</link>

<link name="ARM.1mg996r4">
  <inertial>
    <origin xyz="0.031872 0.024582 -0.133674" rpy="0 0 0"/>
    <mass value="0.0"/>
    <inertia ixx="0.0" iyy="0.0" izz="0.0" ixy="0.0" iyz="0.0" ixz="0.0"/>
  </inertial>
  <visual>
    <origin xyz="0.031872 0.024582 -0.133674" rpy="0 0 0"/>
    <geometry>
      <mesh filename="meshes/ARM.1mg996r4.stl" scale="0.001 0.001 0.001"/>
    </geometry>
    <material name="silver"/>
    <material/>
  </visual>
  <collision>
    <origin xyz="0.031872 0.024582 -0.133674" rpy="0 0 0"/>
    <geometry>
      <mesh filename="meshes/ARM.1mg996r4.stl" scale="0.001 0.001 0.001"/>
    </geometry>
  </collision>
</link>

<link name="ARM.1mg996r5">
  <inertial>
    <origin xyz="0.031872 -0.024618 -0.133674" rpy="0 0 0"/>
    <mass value="0.0"/>
    <inertia ixx="0.0" iyy="0.0" izz="0.0" ixy="0.0" iyz="0.0" ixz="0.0"/>
  </inertial>
  <visual>
    <origin xyz="0.031872 -0.024618 -0.133674" rpy="0 0 0"/>
    <geometry>
      <mesh filename="meshes/ARM.1mg996r5.stl" scale="0.001 0.001 0.001"/>
    </geometry>
    <material name="silver"/>
    <material/>
  </visual>
  <collision>
    <origin xyz="0.031872 -0.024618 -0.133674" rpy="0 0 0"/>
    <geometry>
      <mesh filename="meshes/ARM.1mg996r5.stl" scale="0.001 0.001 0.001"/>
    </geometry>
  </collision>
</link>

<link name="ARM.1mg996r2">
  <inertial>
    <origin xyz="0.070257 -0.024618 -0.124589" rpy="0 0 0"/>
    <mass value="0.0"/>
    <inertia ixx="0.0" iyy="0.0" izz="0.0" ixy="0.0" iyz="0.0" ixz="0.0"/>
  </inertial>
  <visual>
    <origin xyz="0.070257 -0.024618 -0.124589" rpy="0 0 0"/>
    <geometry>
      <mesh filename="meshes/ARM.1mg996r2.stl" scale="0.001 0.001 0.001"/>
    </geometry>
    <material name="silver"/>
    <material/>
  </visual>
  <collision>
    <origin xyz="0.070257 -0.024618 -0.124589" rpy="0 0 0"/>
    <geometry>
      <mesh filename="meshes/ARM.1mg996r2.stl" scale="0.001 0.001 0.001"/>
    </geometry>
  </collision>
</link>

<link name="ARM.1DEFAULT_201">
  <inertial>
    <origin xyz="0.057598 0.154855 -0.078756" rpy="0 0 0"/>
    <mass value="0.0"/>
    <inertia ixx="0.0" iyy="0.0" izz="0.0" ixy="0.0" iyz="0.0" ixz="0.0"/>
  </inertial>
  <visual>
    <origin xyz="0.057598 0.154855 -0.078756" rpy="0 0 0"/>
    <geometry>
      <mesh filename="meshes/ARM.1DEFAULT_201.stl" scale="0.001 0.001 0.001"/>
    </geometry>
    <material name="silver"/>
    <material/>
  </visual>
  <collision>
    <origin xyz="0.057598 0.154855 -0.078756" rpy="0 0 0"/>
    <geometry>
      <mesh filename="meshes/ARM.1DEFAULT_201.stl" scale="0.001 0.001 0.001"/>
    </geometry>
  </collision>
</link>

<link name="ARM.1joint_two_body1">
  <inertial>
    <origin xyz="0.027079 0.154855 -0.080525" rpy="0 0 0"/>
    <mass value="0.0"/>
    <inertia ixx="0.0" iyy="0.0" izz="0.0" ixy="0.0" iyz="0.0" ixz="0.0"/>
  </inertial>
  <visual>
    <origin xyz="0.027079 0.154855 -0.080525" rpy="0 0 0"/>
    <geometry>
      <mesh filename="meshes/ARM.1joint_two_body1.stl" scale="0.001 0.001 0.001"/>
    </geometry>
    <material name="silver"/>
    <material/>
  </visual>
  <collision>
    <origin xyz="0.027079 0.154855 -0.080525" rpy="0 0 0"/>
    <geometry>
      <mesh filename="meshes/ARM.1joint_two_body1.stl" scale="0.001 0.001 0.001"/>
    </geometry>
  </collision>
</link>

<link name="ARM.1mg996r1">
  <inertial>
    <origin xyz="0.009864 0.027191 -0.224361" rpy="0 0 0"/>
    <mass value="0.0"/>
    <inertia ixx="0.0" iyy="0.0" izz="0.0" ixy="0.0" iyz="0.0" ixz="0.0"/>
  </inertial>
  <visual>
    <origin xyz="0.009864 0.027191 -0.224361" rpy="0 0 0"/>
    <geometry>
      <mesh filename="meshes/ARM.1mg996r1.stl" scale="0.001 0.001 0.001"/>
    </geometry>
    <material name="silver"/>
    <material/>
  </visual>
  <collision>
    <origin xyz="0.009864 0.027191 -0.224361" rpy="0 0 0"/>
    <geometry>
      <mesh filename="meshes/ARM.1mg996r1.stl" scale="0.001 0.001 0.001"/>
    </geometry>
  </collision>
</link>

<link name="ARM.1assembly_21joint_three_coupler1">
  <inertial>
    <origin xyz="0.015008 0.010991 -0.210664" rpy="0 0 0"/>
    <mass value="0.0"/>
    <inertia ixx="0.0" iyy="0.0" izz="0.0" ixy="0.0" iyz="0.0" ixz="0.0"/>
  </inertial>
  <visual>
    <origin xyz="0.015008 0.010991 -0.210664" rpy="0 0 0"/>
    <geometry>
      <mesh filename="meshes/ARM.1assembly_21joint_three_coupler1.stl" scale="0.001 0.001 0.001"/>
    </geometry>
    <material name="silver"/>
    <material/>
  </visual>
  <collision>
    <origin xyz="0.015008 0.010991 -0.210664" rpy="0 0 0"/>
    <geometry>
      <mesh filename="meshes/ARM.1assembly_21joint_three_coupler1.stl" scale="0.001 0.001 0.001"/>
    </geometry>
  </collision>
</link>

<link name="ARM.1coupler3">
  <inertial>
    <origin xyz="-0.294455 -0.190175 -0.349438" rpy="0 0 0"/>
    <mass value="0.0"/>
    <inertia ixx="0.0" iyy="0.0" izz="0.0" ixy="0.0" iyz="0.0" ixz="0.0"/>
  </inertial>
  <visual>
    <origin xyz="-0.294455 -0.190175 -0.349438" rpy="0 0 0"/>
    <geometry>
      <mesh filename="meshes/ARM.1coupler3.stl" scale="0.001 0.001 0.001"/>
    </geometry>
    <material name="silver"/>
    <material/>
  </visual>
  <collision>
    <origin xyz="-0.294455 -0.190175 -0.349438" rpy="0 0 0"/>
    <geometry>
      <mesh filename="meshes/ARM.1coupler3.stl" scale="0.001 0.001 0.001"/>
    </geometry>
  </collision>
</link>

<link name="ARM.1DEFAULT_81">
  <inertial>
    <origin xyz="0.001009 0.01576 -0.434339" rpy="0 0 0"/>
    <mass value="0.0"/>
    <inertia ixx="0.0" iyy="0.0" izz="0.0" ixy="0.0" iyz="0.0" ixz="0.0"/>
  </inertial>
  <visual>
    <origin xyz="0.001009 0.01576 -0.434339" rpy="0 0 0"/>
    <geometry>
      <mesh filename="meshes/ARM.1DEFAULT_81.stl" scale="0.001 0.001 0.001"/>
    </geometry>
    <material name="silver"/>
    <material/>
  </visual>
  <collision>
    <origin xyz="0.001009 0.01576 -0.434339" rpy="0 0 0"/>
    <geometry>
      <mesh filename="meshes/ARM.1DEFAULT_81.stl" scale="0.001 0.001 0.001"/>
    </geometry>
  </collision>
</link>

<link name="ARM.1DEFAULT_251">
  <inertial>
    <origin xyz="0.009964 -0.000985 -0.434997" rpy="0 0 0"/>
    <mass value="0.0"/>
    <inertia ixx="0.0" iyy="0.0" izz="0.0" ixy="0.0" iyz="0.0" ixz="0.0"/>
  </inertial>
  <visual>
    <origin xyz="0.009964 -0.000985 -0.434997" rpy="0 0 0"/>
    <geometry>
      <mesh filename="meshes/ARM.1DEFAULT_251.stl" scale="0.001 0.001 0.001"/>
    </geometry>
    <material name="silver"/>
    <material/>
  </visual>
  <collision>
    <origin xyz="0.009964 -0.000985 -0.434997" rpy="0 0 0"/>
    <geometry>
      <mesh filename="meshes/ARM.1DEFAULT_251.stl" scale="0.001 0.001 0.001"/>
    </geometry>
  </collision>
</link>

<link name="ARM.1coupler2">
  <inertial>
    <origin xyz="-0.011594 -0.003481 -0.390498" rpy="0 0 0"/>
    <mass value="0.0"/>
    <inertia ixx="0.0" iyy="0.0" izz="0.0" ixy="0.0" iyz="0.0" ixz="0.0"/>
  </inertial>
  <visual>
    <origin xyz="-0.011594 -0.003481 -0.390498" rpy="0 0 0"/>
    <geometry>
      <mesh filename="meshes/ARM.1coupler2.stl" scale="0.001 0.001 0.001"/>
    </geometry>
    <material name="silver"/>
    <material/>
  </visual>
  <collision>
    <origin xyz="-0.011594 -0.003481 -0.390498" rpy="0 0 0"/>
    <geometry>
      <mesh filename="meshes/ARM.1coupler2.stl" scale="0.001 0.001 0.001"/>
    </geometry>
  </collision>
</link>

<link name="ARM.1small_servo_base3">
  <inertial>
    <origin xyz="0.028672 -0.019295 0.013639" rpy="0 0 0"/>
    <mass value="0.0"/>
    <inertia ixx="0.0" iyy="0.0" izz="0.0" ixy="0.0" iyz="0.0" ixz="0.0"/>
  </inertial>
  <visual>
    <origin xyz="0.028672 -0.019295 0.013639" rpy="0 0 0"/>
    <geometry>
      <mesh filename="meshes/ARM.1small_servo_base3.stl" scale="0.001 0.001 0.001"/>
    </geometry>
    <material name="silver"/>
    <material/>
  </visual>
  <collision>
    <origin xyz="0.028672 -0.019295 0.013639" rpy="0 0 0"/>
    <geometry>
      <mesh filename="meshes/ARM.1small_servo_base3.stl" scale="0.001 0.001 0.001"/>
    </geometry>
  </collision>
</link>

<link name="ARM.1joint_five_body1">
  <inertial>
    <origin xyz="-0.180689 -0.127759 -0.374982" rpy="0 0 0"/>
    <mass value="0.0"/>
    <inertia ixx="0.0" iyy="0.0" izz="0.0" ixy="0.0" iyz="0.0" ixz="0.0"/>
  </inertial>
  <visual>
    <origin xyz="-0.180689 -0.127759 -0.374982" rpy="0 0 0"/>
    <geometry>
      <mesh filename="meshes/ARM.1joint_five_body1.stl" scale="0.001 0.001 0.001"/>
    </geometry>
    <material name="silver"/>
    <material/>
  </visual>
  <collision>
    <origin xyz="-0.180689 -0.127759 -0.374982" rpy="0 0 0"/>
    <geometry>
      <mesh filename="meshes/ARM.1joint_five_body1.stl" scale="0.001 0.001 0.001"/>
    </geometry>
  </collision>
</link>

<link name="ARM.1gripper_coupler1">
  <inertial>
    <origin xyz="-0.036041 0.007949 -0.619692" rpy="0 0 0"/>
    <mass value="0.0"/>
    <inertia ixx="0.0" iyy="0.0" izz="0.0" ixy="0.0" iyz="0.0" ixz="0.0"/>
  </inertial>
  <visual>
    <origin xyz="-0.036041 0.007949 -0.619692" rpy="0 0 0"/>
    <geometry>
      <mesh filename="meshes/ARM.1gripper_coupler1.stl" scale="0.001 0.001 0.001"/>
    </geometry>
    <material name="silver"/>
    <material/>
  </visual>
  <collision>
    <origin xyz="-0.036041 0.007949 -0.619692" rpy="0 0 0"/>
    <geometry>
      <mesh filename="meshes/ARM.1gripper_coupler1.stl" scale="0.001 0.001 0.001"/>
    </geometry>
  </collision>
</link>

<link name="ARM.1gripper_body1">
  <inertial>
    <origin xyz="-0.012239 -0.003481 -0.399275" rpy="0 0 0"/>
    <mass value="0.0"/>
    <inertia ixx="0.0" iyy="0.0" izz="0.0" ixy="0.0" iyz="0.0" ixz="0.0"/>
  </inertial>
  <visual>
    <origin xyz="-0.012239 -0.003481 -0.399275" rpy="0 0 0"/>
    <geometry>
      <mesh filename="meshes/ARM.1gripper_body1.stl" scale="0.001 0.001 0.001"/>
    </geometry>
    <material name="silver"/>
    <material/>
  </visual>
  <collision>
    <origin xyz="-0.012239 -0.003481 -0.399275" rpy="0 0 0"/>
    <geometry>
      <mesh filename="meshes/ARM.1gripper_body1.stl" scale="0.001 0.001 0.001"/>
    </geometry>
  </collision>
</link>

<link name="ARM.1small_servo_base2">
  <inertial>
    <origin xyz="0.304509 0.209602 -0.39283" rpy="0 0 0"/>
    <mass value="0.0"/>
    <inertia ixx="0.0" iyy="0.0" izz="0.0" ixy="0.0" iyz="0.0" ixz="0.0"/>
  </inertial>
  <visual>
    <origin xyz="0.304509 0.209602 -0.39283" rpy="0 0 0"/>
    <geometry>
      <mesh filename="meshes/ARM.1small_servo_base2.stl" scale="0.001 0.001 0.001"/>
    </geometry>
    <material name="silver"/>
    <material/>
  </visual>
  <collision>
    <origin xyz="0.304509 0.209602 -0.39283" rpy="0 0 0"/>
    <geometry>
      <mesh filename="meshes/ARM.1small_servo_base2.stl" scale="0.001 0.001 0.001"/>
    </geometry>
  </collision>
</link>

<link name="ARM.1mg996r1DEFAULT_5_21">
  <inertial>
    <origin xyz="0.014848 0.053091 -0.225913" rpy="0 0 0"/>
    <mass value="0.0"/>
    <inertia ixx="0.0" iyy="0.0" izz="0.0" ixy="0.0" iyz="0.0" ixz="0.0"/>
  </inertial>
  <visual>
    <origin xyz="0.014848 0.053091 -0.225913" rpy="0 0 0"/>
    <geometry>
      <mesh filename="meshes/ARM.1mg996r1DEFAULT_5_21.stl" scale="0.001 0.001 0.001"/>
    </geometry>
    <material name="silver"/>
    <material/>
  </visual>
  <collision>
    <origin xyz="0.014848 0.053091 -0.225913" rpy="0 0 0"/>
    <geometry>
      <mesh filename="meshes/ARM.1mg996r1DEFAULT_5_21.stl" scale="0.001 0.001 0.001"/>
    </geometry>
  </collision>
</link>

<link name="ARM.1gripper_body1DEFAULT1">
  <inertial>
    <origin xyz="0.005706 0.007387 -0.431676" rpy="0 0 0"/>
    <mass value="0.0"/>
    <inertia ixx="0.0" iyy="0.0" izz="0.0" ixy="0.0" iyz="0.0" ixz="0.0"/>
  </inertial>
  <visual>
    <origin xyz="0.005706 0.007387 -0.431676" rpy="0 0 0"/>
    <geometry>
      <mesh filename="meshes/ARM.1gripper_body1DEFAULT1.stl" scale="0.001 0.001 0.001"/>
    </geometry>
    <material name="silver"/>
    <material/>
  </visual>
  <collision>
    <origin xyz="0.005706 0.007387 -0.431676" rpy="0 0 0"/>
    <geometry>
      <mesh filename="meshes/ARM.1gripper_body1DEFAULT1.stl" scale="0.001 0.001 0.001"/>
    </geometry>
  </collision>
</link>

<link name="ARM.1gripper_body1bar11">
  <inertial>
    <origin xyz="0.054643 0.011907 0.013304" rpy="0 0 0"/>
    <mass value="0.0"/>
    <inertia ixx="0.0" iyy="0.0" izz="0.0" ixy="0.0" iyz="0.0" ixz="0.0"/>
  </inertial>
  <visual>
    <origin xyz="0.054643 0.011907 0.013304" rpy="0 0 0"/>
    <geometry>
      <mesh filename="meshes/ARM.1gripper_body1bar11.stl" scale="0.001 0.001 0.001"/>
    </geometry>
    <material name="silver"/>
    <material/>
  </visual>
  <collision>
    <origin xyz="0.054643 0.011907 0.013304" rpy="0 0 0"/>
    <geometry>
      <mesh filename="meshes/ARM.1gripper_body1bar11.stl" scale="0.001 0.001 0.001"/>
    </geometry>
  </collision>
</link>

<link name="ARM.1gripper_body1bar21">
  <inertial>
    <origin xyz="0.054712 -0.007082 0.013959" rpy="0 0 0"/>
    <mass value="0.0"/>
    <inertia ixx="0.0" iyy="0.0" izz="0.0" ixy="0.0" iyz="0.0" ixz="0.0"/>
  </inertial>
  <visual>
    <origin xyz="0.054712 -0.007082 0.013959" rpy="0 0 0"/>
    <geometry>
      <mesh filename="meshes/ARM.1gripper_body1bar21.stl" scale="0.001 0.001 0.001"/>
    </geometry>
    <material name="silver"/>
    <material/>
  </visual>
  <collision>
    <origin xyz="0.054712 -0.007082 0.013959" rpy="0 0 0"/>
    <geometry>
      <mesh filename="meshes/ARM.1gripper_body1bar21.stl" scale="0.001 0.001 0.001"/>
    </geometry>
  </collision>
</link>

<link name="ARM.1mg996r2DEFAULT_5_21">
  <inertial>
    <origin xyz="0.014848 0.053091 -0.225913" rpy="0 0 0"/>
    <mass value="0.0"/>
    <inertia ixx="0.0" iyy="0.0" izz="0.0" ixy="0.0" iyz="0.0" ixz="0.0"/>
  </inertial>
  <visual>
    <origin xyz="0.014848 0.053091 -0.225913" rpy="0 0 0"/>
    <geometry>
      <mesh filename="meshes/ARM.1mg996r2DEFAULT_5_21.stl" scale="0.001 0.001 0.001"/>
    </geometry>
    <material name="silver"/>
    <material/>
  </visual>
  <collision>
    <origin xyz="0.014848 0.053091 -0.225913" rpy="0 0 0"/>
    <geometry>
      <mesh filename="meshes/ARM.1mg996r2DEFAULT_5_21.stl" scale="0.001 0.001 0.001"/>
    </geometry>
  </collision>
</link>

<link name="ARM.1mg996r4DEFAULT_5_21">
  <inertial>
    <origin xyz="0.014848 0.053091 -0.225913" rpy="0 0 0"/>
    <mass value="0.0"/>
    <inertia ixx="0.0" iyy="0.0" izz="0.0" ixy="0.0" iyz="0.0" ixz="0.0"/>
  </inertial>
  <visual>
    <origin xyz="0.014848 0.053091 -0.225913" rpy="0 0 0"/>
    <geometry>
      <mesh filename="meshes/ARM.1mg996r4DEFAULT_5_21.stl" scale="0.001 0.001 0.001"/>
    </geometry>
    <material name="silver"/>
    <material/>
  </visual>
  <collision>
    <origin xyz="0.014848 0.053091 -0.225913" rpy="0 0 0"/>
    <geometry>
      <mesh filename="meshes/ARM.1mg996r4DEFAULT_5_21.stl" scale="0.001 0.001 0.001"/>
    </geometry>
  </collision>
</link>

<link name="ARM.1mg996r5DEFAULT_5_21">
  <inertial>
    <origin xyz="0.014848 0.053091 -0.225913" rpy="0 0 0"/>
    <mass value="0.0"/>
    <inertia ixx="0.0" iyy="0.0" izz="0.0" ixy="0.0" iyz="0.0" ixz="0.0"/>
  </inertial>
  <visual>
    <origin xyz="0.014848 0.053091 -0.225913" rpy="0 0 0"/>
    <geometry>
      <mesh filename="meshes/ARM.1mg996r5DEFAULT_5_21.stl" scale="0.001 0.001 0.001"/>
    </geometry>
    <material name="silver"/>
    <material/>
  </visual>
  <collision>
    <origin xyz="0.014848 0.053091 -0.225913" rpy="0 0 0"/>
    <geometry>
      <mesh filename="meshes/ARM.1mg996r5DEFAULT_5_21.stl" scale="0.001 0.001 0.001"/>
    </geometry>
  </collision>
</link>

<link name="ARM.1assembly_21coupler1">
  <inertial>
    <origin xyz="-0.029402 -0.00219 -0.588775" rpy="0 0 0"/>
    <mass value="0.0"/>
    <inertia ixx="0.0" iyy="0.0" izz="0.0" ixy="0.0" iyz="0.0" ixz="0.0"/>
  </inertial>
  <visual>
    <origin xyz="-0.029402 -0.00219 -0.588775" rpy="0 0 0"/>
    <geometry>
      <mesh filename="meshes/ARM.1assembly_21coupler1.stl" scale="0.001 0.001 0.001"/>
    </geometry>
    <material name="silver"/>
    <material/>
  </visual>
  <collision>
    <origin xyz="-0.029402 -0.00219 -0.588775" rpy="0 0 0"/>
    <geometry>
      <mesh filename="meshes/ARM.1assembly_21coupler1.stl" scale="0.001 0.001 0.001"/>
    </geometry>
  </collision>
</link>

<link name="ARM.1assembly_21joint_four_body1">
  <inertial>
    <origin xyz="0.013383 0.001291 -0.234158" rpy="0 0 0"/>
    <mass value="0.0"/>
    <inertia ixx="0.0" iyy="0.0" izz="0.0" ixy="0.0" iyz="0.0" ixz="0.0"/>
  </inertial>
  <visual>
    <origin xyz="0.013383 0.001291 -0.234158" rpy="0 0 0"/>
    <geometry>
      <mesh filename="meshes/ARM.1assembly_21joint_four_body1.stl" scale="0.001 0.001 0.001"/>
    </geometry>
    <material name="silver"/>
    <material/>
  </visual>
  <collision>
    <origin xyz="0.013383 0.001291 -0.234158" rpy="0 0 0"/>
    <geometry>
      <mesh filename="meshes/ARM.1assembly_21joint_four_body1.stl" scale="0.001 0.001 0.001"/>
    </geometry>
  </collision>
</link>

<link name="ARM.1assembly_21joint_four_bearing1">
  <inertial>
    <origin xyz="0.004651 0.001291 -0.353038" rpy="0 0 0"/>
    <mass value="0.0"/>
    <inertia ixx="0.0" iyy="0.0" izz="0.0" ixy="0.0" iyz="0.0" ixz="0.0"/>
  </inertial>
  <visual>
    <origin xyz="0.004651 0.001291 -0.353038" rpy="0 0 0"/>
    <geometry>
      <mesh filename="meshes/ARM.1assembly_21joint_four_bearing1.stl" scale="0.001 0.001 0.001"/>
    </geometry>
    <material name="silver"/>
    <material/>
  </visual>
  <collision>
    <origin xyz="0.004651 0.001291 -0.353038" rpy="0 0 0"/>
    <geometry>
      <mesh filename="meshes/ARM.1assembly_21joint_four_bearing1.stl" scale="0.001 0.001 0.001"/>
    </geometry>
  </collision>
</link>

<link name="ARM.1assembly_21joint_three_body1">
  <inertial>
    <origin xyz="0.02367 -0.009333 -0.237771" rpy="0 0 0"/>
    <mass value="0.0"/>
    <inertia ixx="0.0" iyy="0.0" izz="0.0" ixy="0.0" iyz="0.0" ixz="0.0"/>
  </inertial>
  <visual>
    <origin xyz="0.02367 -0.009333 -0.237771" rpy="0 0 0"/>
    <geometry>
      <mesh filename="meshes/ARM.1assembly_21joint_three_body1.stl" scale="0.001 0.001 0.001"/>
    </geometry>
    <material name="silver"/>
    <material/>
  </visual>
  <collision>
    <origin xyz="0.02367 -0.009333 -0.237771" rpy="0 0 0"/>
    <geometry>
      <mesh filename="meshes/ARM.1assembly_21joint_three_body1.stl" scale="0.001 0.001 0.001"/>
    </geometry>
  </collision>
</link>

<link name="ARM.1assembly_21small_servo_base1">
  <inertial>
    <origin xyz="0.021383 -0.012792 -0.026372" rpy="0 0 0"/>
    <mass value="0.0"/>
    <inertia ixx="0.0" iyy="0.0" izz="0.0" ixy="0.0" iyz="0.0" ixz="0.0"/>
  </inertial>
  <visual>
    <origin xyz="0.021383 -0.012792 -0.026372" rpy="0 0 0"/>
    <geometry>
      <mesh filename="meshes/ARM.1assembly_21small_servo_base1.stl" scale="0.001 0.001 0.001"/>
    </geometry>
    <material name="silver"/>
    <material/>
  </visual>
  <collision>
    <origin xyz="0.021383 -0.012792 -0.026372" rpy="0 0 0"/>
    <geometry>
      <mesh filename="meshes/ARM.1assembly_21small_servo_base1.stl" scale="0.001 0.001 0.001"/>
    </geometry>
  </collision>
</link>

<joint name="ARM.1_Revolute 3" type="revolute">
  <origin xyz="9e-06 9e-06 0.009" rpy="0 0 0"/>
  <parent link="base_link"/>
  <child link="ARM.1base_servo1"/>
  <axis xyz="0.0 0.0 1.0"/>
  <limit upper="1.570796" lower="-1.570796" effort="100" velocity="100"/>
</joint>
<transmission name="ARM.1_Revolute 3_tran">
  <type>transmission_interface/SimpleTransmission</type>
  <joint name="ARM.1_Revolute 3">
    <hardwareInterface>PositionJointInterface</hardwareInterface>
  </joint>
  <actuator name="ARM.1_Revolute 3_actr">
    <hardwareInterface>PositionJointInterface</hardwareInterface>
    <mechanicalReduction>1</mechanicalReduction>
  </actuator>
</transmission>

<joint name="ARM.1_Rigid 4" type="fixed">
  <origin xyz="-0.03415 0.0 0.0186" rpy="0 0 0"/>
  <parent link="ARM.1base_servo1"/>
  <child link="ARM.1joint_one_body1"/>
</joint>

<joint name="ARM.1_Rigid 5" type="fixed">
  <origin xyz="0.002269 -0.024591 0.106074" rpy="0 0 0"/>
  <parent link="ARM.1joint_one_body1"/>
  <child link="ARM.1mg996r4"/>
</joint>

<joint name="ARM.1_Rigid 6" type="fixed">
  <origin xyz="0.002269 0.024609 0.106074" rpy="0 0 0"/>
  <parent link="ARM.1joint_one_body1"/>
  <child link="ARM.1mg996r5"/>
</joint>

<joint name="ARM.1_Rigid 7" type="fixed">
  <origin xyz="-0.036116 0.024609 0.096989" rpy="0 0 0"/>
  <parent link="ARM.1joint_one_body1"/>
  <child link="ARM.1mg996r2"/>
</joint>

<joint name="ARM.1_Revolute 8" type="continuous">
  <origin xyz="0.012659 -0.179473 -0.045833" rpy="0 0 0"/>
  <parent link="ARM.1mg996r2"/>
  <child link="ARM.1DEFAULT_201"/>
  <axis xyz="-0.0 -1.0 -0.0"/>
</joint>
<transmission name="ARM.1_Revolute 8_tran">
  <type>transmission_interface/SimpleTransmission</type>
  <joint name="ARM.1_Revolute 8">
    <hardwareInterface>PositionJointInterface</hardwareInterface>
  </joint>
  <actuator name="ARM.1_Revolute 8_actr">
    <hardwareInterface>PositionJointInterface</hardwareInterface>
    <mechanicalReduction>1</mechanicalReduction>
  </actuator>
</transmission>

<joint name="ARM.1_Revolute 9" type="revolute">
  <origin xyz="0.004793 -0.179473 -0.053149" rpy="0 0 0"/>
  <parent link="ARM.1mg996r5"/>
  <child link="ARM.1joint_two_body1"/>
  <axis xyz="-0.0 -1.0 -0.0"/>
  <limit upper="1.570796" lower="-1.570796" effort="100" velocity="100"/>
</joint>
<transmission name="ARM.1_Revolute 9_tran">
  <type>transmission_interface/SimpleTransmission</type>
  <joint name="ARM.1_Revolute 9">
    <hardwareInterface>PositionJointInterface</hardwareInterface>
  </joint>
  <actuator name="ARM.1_Revolute 9_actr">
    <hardwareInterface>PositionJointInterface</hardwareInterface>
    <mechanicalReduction>1</mechanicalReduction>
  </actuator>
</transmission>

<joint name="ARM.1_Rigid 10" type="fixed">
  <origin xyz="0.017215 0.127664 0.143836" rpy="0 0 0"/>
  <parent link="ARM.1joint_two_body1"/>
  <child link="ARM.1mg996r1"/>
</joint>

<joint name="ARM.1_Revolute 11" type="revolute">
  <origin xyz="-0.005144 0.0162 -0.013697" rpy="0 0 0"/>
  <parent link="ARM.1mg996r1"/>
  <child link="ARM.1assembly_21joint_three_coupler1"/>
  <axis xyz="0.0 1.0 0.0"/>
  <limit upper="0.785398" lower="-2.356194" effort="100" velocity="100"/>
</joint>
<transmission name="ARM.1_Revolute 11_tran">
  <type>transmission_interface/SimpleTransmission</type>
  <joint name="ARM.1_Revolute 11">
    <hardwareInterface>PositionJointInterface</hardwareInterface>
  </joint>
  <actuator name="ARM.1_Revolute 11_actr">
    <hardwareInterface>PositionJointInterface</hardwareInterface>
    <mechanicalReduction>1</mechanicalReduction>
  </actuator>
</transmission>

<joint name="ARM.1_Revolute 14" type="revolute">
  <origin xyz="0.323127 0.17088 0.363077" rpy="0 0 0"/>
  <parent link="ARM.1small_servo_base3"/>
  <child link="ARM.1coupler3"/>
  <axis xyz="0.81528 0.575963 -0.05988"/>
  <limit upper="3.141593" lower="0.0" effort="100" velocity="100"/>
</joint>
<transmission name="ARM.1_Revolute 14_tran">
  <type>transmission_interface/SimpleTransmission</type>
  <joint name="ARM.1_Revolute 14">
    <hardwareInterface>PositionJointInterface</hardwareInterface>
  </joint>
  <actuator name="ARM.1_Revolute 14_actr">
    <hardwareInterface>PositionJointInterface</hardwareInterface>
    <mechanicalReduction>1</mechanicalReduction>
  </actuator>
</transmission>

<joint name="ARM.1_Slider 17" type="prismatic">
  <origin xyz="0.053634 -0.003853 0.447643" rpy="0 0 0"/>
  <parent link="ARM.1gripper_body1bar11"/>
  <child link="ARM.1DEFAULT_81"/>
  <axis xyz="-0.87894 -0.472543 0.064556"/>
  <limit upper="-0.016" lower="-0.035" effort="100" velocity="100"/>
</joint>
<transmission name="ARM.1_Slider 17_tran">
  <type>transmission_interface/SimpleTransmission</type>
  <joint name="ARM.1_Slider 17">
    <hardwareInterface>PositionJointInterface</hardwareInterface>
  </joint>
  <actuator name="ARM.1_Slider 17_actr">
    <hardwareInterface>PositionJointInterface</hardwareInterface>
    <mechanicalReduction>1</mechanicalReduction>
  </actuator>
</transmission>

<joint name="ARM.1_Slider 18" type="prismatic">
  <origin xyz="0.044748 -0.006097 0.448956" rpy="0 0 0"/>
  <parent link="ARM.1gripper_body1bar21"/>
  <child link="ARM.1DEFAULT_251"/>
  <axis xyz="-0.87894 -0.472543 0.064556"/>
  <limit upper="-0.011" lower="-0.035" effort="100" velocity="100"/>
</joint>
<transmission name="ARM.1_Slider 18_tran">
  <type>transmission_interface/SimpleTransmission</type>
  <joint name="ARM.1_Slider 18">
    <hardwareInterface>PositionJointInterface</hardwareInterface>
  </joint>
  <actuator name="ARM.1_Slider 18_actr">
    <hardwareInterface>PositionJointInterface</hardwareInterface>
    <mechanicalReduction>1</mechanicalReduction>
  </actuator>
</transmission>

<joint name="ARM.1_Revolute 19" type="revolute">
  <origin xyz="0.316103 0.213083 -0.002332" rpy="0 0 0"/>
  <parent link="ARM.1small_servo_base2"/>
  <child link="ARM.1coupler2"/>
  <axis xyz="0.07325 -0.0 0.997314"/>
  <limit upper="3.141593" lower="0.0" effort="100" velocity="100"/>
</joint>
<transmission name="ARM.1_Revolute 19_tran">
  <type>transmission_interface/SimpleTransmission</type>
  <joint name="ARM.1_Revolute 19">
    <hardwareInterface>PositionJointInterface</hardwareInterface>
  </joint>
  <actuator name="ARM.1_Revolute 19_actr">
    <hardwareInterface>PositionJointInterface</hardwareInterface>
    <mechanicalReduction>1</mechanicalReduction>
  </actuator>
</transmission>

<joint name="ARM.1_Rigid 20" type="fixed">
  <origin xyz="-0.015289 0.020586 -0.247797" rpy="0 0 0"/>
  <parent link="ARM.1assembly_21joint_four_body1"/>
  <child link="ARM.1small_servo_base3"/>
</joint>

<joint name="ARM.1_Rigid 21" type="fixed">
  <origin xyz="-0.113766 -0.062416 0.025544" rpy="0 0 0"/>
  <parent link="ARM.1coupler3"/>
  <child link="ARM.1joint_five_body1"/>
</joint>

<joint name="ARM.1_Rigid 22" type="fixed">
  <origin xyz="0.024447 -0.01143 0.229194" rpy="0 0 0"/>
  <parent link="ARM.1coupler2"/>
  <child link="ARM.1gripper_coupler1"/>
</joint>

<joint name="ARM.1_Rigid 23" type="fixed">
  <origin xyz="-0.023802 0.01143 -0.220417" rpy="0 0 0"/>
  <parent link="ARM.1gripper_coupler1"/>
  <child link="ARM.1gripper_body1"/>
</joint>

<joint name="ARM.1_Rigid 24" type="fixed">
  <origin xyz="-0.485198 -0.337361 0.017848" rpy="0 0 0"/>
  <parent link="ARM.1joint_five_body1"/>
  <child link="ARM.1small_servo_base2"/>
</joint>

<joint name="ARM.1mg996r1_Rigid 2" type="fixed">
  <origin xyz="-0.004984 -0.0259 0.001552" rpy="0 0 0"/>
  <parent link="ARM.1mg996r1"/>
  <child link="ARM.1mg996r1DEFAULT_5_21"/>
</joint>

<joint name="ARM.1gripper_body1_Rigid 16" type="fixed">
  <origin xyz="-0.017945 -0.010868 0.032401" rpy="0 0 0"/>
  <parent link="ARM.1gripper_body1"/>
  <child link="ARM.1gripper_body1DEFAULT1"/>
</joint>

<joint name="ARM.1gripper_body1_Rigid 2" type="fixed">
  <origin xyz="-0.066882 -0.015388 -0.412579" rpy="0 0 0"/>
  <parent link="ARM.1gripper_body1"/>
  <child link="ARM.1gripper_body1bar11"/>
</joint>

<joint name="ARM.1gripper_body1_Rigid 3" type="fixed">
  <origin xyz="-0.066951 0.003601 -0.413234" rpy="0 0 0"/>
  <parent link="ARM.1gripper_body1"/>
  <child link="ARM.1gripper_body1bar21"/>
</joint>

<joint name="ARM.1mg996r2_Rigid 2" type="fixed">
  <origin xyz="0.055409 -0.077709 0.101324" rpy="0 0 0"/>
  <parent link="ARM.1mg996r2"/>
  <child link="ARM.1mg996r2DEFAULT_5_21"/>
</joint>

<joint name="ARM.1mg996r4_Rigid 2" type="fixed">
  <origin xyz="0.017024 -0.028509 0.092239" rpy="0 0 0"/>
  <parent link="ARM.1mg996r4"/>
  <child link="ARM.1mg996r4DEFAULT_5_21"/>
</joint>

<joint name="ARM.1mg996r5_Rigid 2" type="fixed">
  <origin xyz="0.017024 -0.077709 0.092239" rpy="0 0 0"/>
  <parent link="ARM.1mg996r5"/>
  <child link="ARM.1mg996r5DEFAULT_5_21"/>
</joint>

<joint name="ARM.1assembly_21_Rigid 5" type="fixed">
  <origin xyz="0.050785 -0.010602 0.562403" rpy="0 0 0"/>
  <parent link="ARM.1assembly_21small_servo_base1"/>
  <child link="ARM.1assembly_21coupler1"/>
</joint>

<joint name="ARM.1assembly_21_Revolute 6" type="revolute">
  <origin xyz="-0.042785 -0.003481 -0.354617" rpy="0 0 0"/>
  <parent link="ARM.1assembly_21coupler1"/>
  <child link="ARM.1assembly_21joint_four_body1"/>
  <axis xyz="0.07325 -0.0 0.997314"/>
  <limit upper="1.570796" lower="-1.570796" effort="100" velocity="100"/>
</joint>
<transmission name="ARM.1assembly_21_Revolute 6_tran">
  <type>transmission_interface/SimpleTransmission</type>
  <joint name="ARM.1assembly_21_Revolute 6">
    <hardwareInterface>PositionJointInterface</hardwareInterface>
  </joint>
  <actuator name="ARM.1assembly_21_Revolute 6_actr">
    <hardwareInterface>PositionJointInterface</hardwareInterface>
    <mechanicalReduction>1</mechanicalReduction>
  </actuator>
</transmission>

<joint name="ARM.1assembly_21_Rigid 7" type="fixed">
  <origin xyz="0.008732 0.0 0.11888" rpy="0 0 0"/>
  <parent link="ARM.1assembly_21joint_four_body1"/>
  <child link="ARM.1assembly_21joint_four_bearing1"/>
</joint>

<joint name="ARM.1assembly_21_Rigid 8" type="fixed">
  <origin xyz="-0.008662 0.020324 0.027107" rpy="0 0 0"/>
  <parent link="ARM.1assembly_21joint_three_coupler1"/>
  <child link="ARM.1assembly_21joint_three_body1"/>
</joint>

<joint name="ARM.1assembly_21_Rigid 9" type="fixed">
  <origin xyz="-0.006375 0.023783 -0.184292" rpy="0 0 0"/>
  <parent link="ARM.1assembly_21joint_three_coupler1"/>
  <child link="ARM.1assembly_21small_servo_base1"/>
</joint>

</robot>
